Workbook

Sheet summary
B4: data source:
B5: https://hercules.properties/research/nyc-biggest-sales/2026-01
B8: 125 3rd Street, Brooklyn, NY 11231 is one $105,000,000 sale in the January 2026 ranking. The closing date on the condo units is December 30, 2025. The deed was recorded on January 13, 2026, which is why it appears in the January list.
B9: The building is a 14-story condominium (class RM), finished in 2024, with 3 residential units and 4 units in total.
F13: 105000000 | G13: 106000 | H13: =F13/G13 -> 990.56604

Sheet 2026 transactions
A1: Date of transaction | B1: Value of transaction | C1: Property | D1: Square foot of building | E1: Year built | F1: USD/sqft
A2: 46028 | B2: 55000000 | C2: 119-09 26 AVENUE, Queens, NY 11354 | D2: 76000 | E2: 1968 | F2: =IF(OR(D2="",D2=0),"",B2/D2) -> 723.68421
A3: 46028 | B3: 34500000 | C3: 48-02 30 PLACE, Queens, NY 11101 | D3: 141436 | E3: 1926 | F3: =IF(OR(D3="",D3=0),"",B3/D3) -> 243.92658
A4: 46028 | B4: 2200000 | C4: 1710 BRONXDALE AVENUE, Bronx, NY 10462 | D4: 8082 | E4: 1955 | F4: =IF(OR(D4="",D4=0),"",B4/D4) -> 272.20985
A5: 46029 | B5: 63000000 | C5: 183 VARICK STREET, Manhattan, NY 10014 | D5: 68476 | E5: 1930 | F5: =IF(OR(D5="",D5=0),"",B5/D5) -> 920.03038
A6: 46030 | B6: 71000000 | C6: 410 WEST 13 STREET, Manhattan, NY 10014 | D6: 66893 | E6: 2008 | F6: =IF(OR(D6="",D6=0),"",B6/D6) -> 1061.3966
A7: 46031 | B7: 55635125 | C7: 50 WEST 66TH STREET, Manhattan, NY 10023 | D7: 469906 | E7: 2019 | F7: =IF(OR(D7="",D7=0),"",B7/D7) -> 118.39629
A8: 46031 | B8: 15192561 | C8: 4275 BOSTON ROAD, Bronx, NY 10466 | D8: 72248 | E8: 1970 | F8: =IF(OR(D8="",D8=0),"",B8/D8) -> 210.28348
A9: 46034 | B9: 53000000 | C9: 63 CROSBY STREET, Manhattan, NY 10012 | D9: 27930 | E9: 1900 | F9: =IF(OR(D9="",D9=0),"",B9/D9) -> 1897.6011
A10: 46034 | B10: 30985004 | C10: 163-25 ARCHER AVENUE, Queens, NY 11433 | F10: =IF(OR(D10="",D10=0),"",B10/D10)
A11: 46035 | B11: 2.9779746e+08 | C11: 40-22 COLLEGE POINT BLVD, Queens, NY 11354 | D11: 1591806 | E11: 2006 | F11: =IF(OR(D11="",D11=0),"",B11/D11) -> 187.0815
A12: 46035 | B12: 141000000 | C12: 3 EAST 54 STREET, Manhattan, NY 10022 | D12: 283465 | E12: 1955 | F12: =IF(OR(D12="",D12=0),"",B12/D12) -> 497.41591
A13: 46035 | B13: 1.0970831e+08 | C13: 40-22 COLLEGE POINT BLVD, Queens, NY 11354 | D13: 1591806 | E13: 2006 | F13: =IF(OR(D13="",D13=0),"",B13/D13) -> 68.920654
A14: 46035 | B14: 105000000 | C14: 125 3RD STREET, Brooklyn, NY 11231 | D14: 106516 | E14: 2024 | F14: =IF(OR(D14="",D14=0),"",B14/D14) -> 985.7674
A15: 46035 | B15: 5150000 | C15: 1741 PILGRIM AVENUE, Bronx, NY 10461 | D15: 34031 | E15: 1927 | F15: =IF(OR(D15="",D15=0),"",B15/D15) -> 151.33261
A16: 46035 | B16: 3050000 | C16: 1770 MAHAN AVENUE, Bronx, NY 10461 | D16: 23875 | E16: 1927 | F16: =IF(OR(D16="",D16=0),"",B16/D16) -> 127.74869
A17: 46036 | B17: 53000000 | C17: 75 NASSAU STREET, Manhattan, NY 10038 | F17: =IF(OR(D17="",D17=0),"",B17/D17)
A18: 46037 | B18: 46181250 | C18: 541 WEST 21 STREET, Manhattan, NY 10011 | D18: 55141 | E18: 1915 | F18: =IF(OR(D18="",D18=0),"",B18/D18) -> 837.51201
A19: 46038 | B19: 50700000 | C19: 1 COLUMBUS CIRCLE, Manhattan, NY 10019 | D19: 2101982 | E19: 2004 | F19: =IF(OR(D19="",D19=0),"",B19/D19) -> 24.120092
A20: 46042 | B20: 10000000 | C20: 726 40 STREET, Brooklyn, NY 11232 | D20: 6750 | E20: 1913 | F20: =IF(OR(D20="",D20=0),"",B20/D20) -> 1481.4815
A21: 46043 | B21: 77002366 | C21: 1 PARK ROW, Manhattan, NY 10038 | D21: 77202 | E21: 2023 | F21: =IF(OR(D21="",D21=0),"",B21/D21) -> 997.41413
A22: 46043 | B22: 20000000 | C22: 31-69 COLLEGE POINT BOULEVARD, Queens, NY 11354 | D22: 20544 | E22: 1994 | F22: =IF(OR(D22="",D22=0),"",B22/D22) -> 973.52025
A23: 46043 | B23: 7200000 | C23: 1261 ZEREGA AVENUE, Bronx, NY 10462 | D23: 28926 | E23: 1964 | F23: =IF(OR(D23="",D23=0),"",B23/D23) -> 248.91101
A24: 46043 | B24: 4800000 | C24: 360 EAST GUN HILL ROAD, Bronx, NY 10467 | D24: 18207 | E24: 1922 | F24: =IF(OR(D24="",D24=0),"",B24/D24) -> 263.63487
A25: 46044 | B25: 52956368 | C25: 59 WEST 46 STREET, Manhattan, NY 10036 | D25: 100678 | E25: 1906 | F25: =IF(OR(D25="",D25=0),"",B25/D25) -> 525.99742
A26: 46044 | B26: 43700000 | C26: 90 WOOSTER STREET, Manhattan, NY 10012 | D26: 16123 | E26: 1890 | F26: =IF(OR(D26="",D26=0),"",B26/D26) -> 2710.4137
A27: 46044 | B27: 9163690 | C27: CORTELYOU ROAD, Brooklyn, NY 11218 | F27: =IF(OR(D27="",D27=0),"",B27/D27)
A28: 46044 | B28: 2400000 | C28: 4663 3 AVENUE, Bronx, NY 10458 | D28: 12700 | E28: 1931 | F28: =IF(OR(D28="",D28=0),"",B28/D28) -> 188.97638
A29: 46048 | B29: 145523540 | C29: 72 CATON PLACE, Brooklyn, NY 11218 | D29: 168034 | E29: 2019 | F29: =IF(OR(D29="",D29=0),"",B29/D29) -> 866.03628
A30: 46048 | B30: 119681966 | C30: 31-08 NORTHERN BLVD, Queens, NY 11101 | D30: 245910 | E30: 2020 | F30: =IF(OR(D30="",D30=0),"",B30/D30) -> 486.69011
A31: 46048 | B31: 100741078 | C31: 34-09 COLLEGE POINT BLVD, Queens, NY 11354 | D31: 158669 | E31: 2019 | F31: =IF(OR(D31="",D31=0),"",B31/D31) -> 634.91342
A32: 46048 | B32: 88339886 | C32: 2926 FREDRICK DOUGLASS BL, Manhattan, NY 10039 | D32: 109735 | E32: 2021 | F32: =IF(OR(D32="",D32=0),"",B32/D32) -> 805.02926
A33: 46048 | B33: 84687153 | C33: 87-16 121 STREET, Queens, NY 11418 | D33: 154782 | E33: 2020 | F33: =IF(OR(D33="",D33=0),"",B33/D33) -> 547.13825
A34: 46048 | B34: 75651652 | C34: 1 REMSEN AVENUE, Brooklyn, NY 11212 | D34: 111391 | E34: 2011 | F34: =IF(OR(D34="",D34=0),"",B34/D34) -> 679.15408
A35: 46048 | B35: 71749825 | C35: 62-05 30TH AVENUE, Queens, NY 11377 | D35: 102056 | E35: 2021 | F35: =IF(OR(D35="",D35=0),"",B35/D35) -> 703.04367
A36: 46048 | B36: 57002671 | C36: 154 17 STREET, Brooklyn, NY 11215 | D36: 76888 | E36: 2020 | F36: =IF(OR(D36="",D36=0),"",B36/D36) -> 741.37279
A37: 46048 | B37: 30184181 | C37: 1690 EAST NEW YORK AVENUE, Brooklyn, NY 11212 | D37: 61951 | E37: 2019 | F37: =IF(OR(D37="",D37=0),"",B37/D37) -> 487.2267
A38: 46048 | B38: 26716323 | C38: 507 OSBORN STREET, Brooklyn, NY 11212 | D38: 54858 | E38: 1958 | F38: =IF(OR(D38="",D38=0),"",B38/D38) -> 487.0087
A39: 46048 | B39: 24692433 | C39: 651 UTICA AVENUE, Brooklyn, NY 11203 | D39: 35589 | E39: 2018 | F39: =IF(OR(D39="",D39=0),"",B39/D39) -> 693.82205
... A41: 46050 | B41: 112250000 | C41: 250 EAST HOUSTON STREET, Manhattan, NY 10002 | D41: 122416 | E41: 1989 | F41: =IF(OR(D41="",D41=0),"",B41/D41) -> 916.9553
...

Sheet Plot
A48: Month | B48: 2020 and above | C48: Month | D48: 2000-2019 | E48: Month | F48: 1950-1999 | G48: Month | H48: Before 1950
A49: ='2026 transactions'!A14 -> 46035 | B49: ='2026 transactions'!F14 -> 985.7674 | C49: ='2026 transactions'!A6 -> 46030 | D49: ='2026 transactions'!F6 -> 1061.3966 | E49: ='2026 transactions'!A2 -> 46028 | F49: ='2026 transactions'!F2 -> 723.68421 | G49: ='2026 transactions'!A3 -> 46028 | H49: ='2026 transactions'!F3 -> 243.92658
A50: ='2026 transactions'!A21 -> 46043 | B50: ='2026 transactions'!F21 -> 997.41413 | C50: ='2026 transactions'!A7 -> 46031 | D50: ='2026 transactions'!F7 -> 118.39629 | E50: ='2026 transactions'!A4 -> 46028 | F50: ='2026 transactions'!F4 -> 272.20985 | G50: ='2026 transactions'!A5 -> 46029 | H50: ='2026 transactions'!F5 -> 920.03038
A51: ='2026 transactions'!A30 -> 46048 | B51: ='2026 transactions'!F30 -> 486.69011 | C51: ='2026 transactions'!A11 -> 46035 | D51: ='2026 transactions'!F11 -> 187.0815 | E51: ='2026 transactions'!A8 -> 46031 | F51: ='2026 transactions'!F8 -> 210.28348 | G51: ='2026 transactions'!A9 -> 46034 | H51: ='2026 transactions'!F9 -> 1897.6011
A52: ='2026 transactions'!A32 -> 46048 | B52: ='2026 transactions'!F32 -> 805.02926 | C52: ='2026 transactions'!A13 -> 46035 | D52: ='2026 transactions'!F13 -> 68.920654 | E52: ='2026 transactions'!A12 -> 46035 | F52: ='2026 transactions'!F12 -> 497.41591 | G52: ='2026 transactions'!A15 -> 46035 | H52: ='2026 transactions'!F15 -> 151.33261
A53: ='2026 transactions'!A33 -> 46048 | B53: ='2026 transactions'!F33 -> 547.13825 | C53: ='2026 transactions'!A19 -> 46038 | D53: ='2026 transactions'!F19 -> 24.120092 | E53: ='2026 transactions'!A22 -> 46043 | F53: ='2026 transactions'!F22 -> 973.52025 | G53: ='2026 transactions'!A16 -> 46035 | H53: ='2026 transactions'!F16 -> 127.74869
A54: ='2026 transactions'!A35 -> 46048 | B54: ='2026 transactions'!F35 -> 703.04367 | C54: ='2026 transactions'!A29 -> 46048 | D54: ='2026 transactions'!F29 -> 866.03628 | E54: ='2026 transactions'!A23 -> 46043 | F54: ='2026 transactions'!F23 -> 248.91101 | G54: ='2026 transactions'!A18 -> 46037 | H54: ='2026 transactions'!F18 -> 837.51201
A55: ='2026 transactions'!A36 -> 46048 | B55: ='2026 transactions'!F36 -> 741.37279 | C55: ='2026 transactions'!A31 -> 46048 | D55: ='2026 transactions'!F31 -> 634.91342 | E55: ='2026 transactions'!A38 -> 46048 | F55: ='2026 transactions'!F38 -> 487.0087 | G55: ='2026 transactions'!A20 -> 46042 | H55: ='2026 transactions'!F20 -> 1481.4815
A56: ='2026 transactions'!A55 -> 46065 | B56: ='2026 transactions'!F55 -> 48.379919 | C56: ='2026 transactions'!A34 -> 46048 | D56: ='2026 transactions'!F34 -> 679.15408 | E56: ='2026 transactions'!A41 -> 46050 | F56: ='2026 transactions'!F41 -> 916.9553 | G56: ='2026 transactions'!A24 -> 46043 | H56: ='2026 transactions'!F24 -> 263.63487
A57: ='2026 transactions'!A71 -> 46072 | B57: ='2026 transactions'!F71 -> 363.79454 | C57: ='2026 transactions'!A37 -> 46048 | D57: ='2026 transactions'!F37 -> 487.2267 | E57: ='2026 transactions'!A43 -> 46051 | F57: ='2026 transactions'!F43 -> 1411.9601 | G57: ='2026 transactions'!A25 -> 46044 | H57: ='2026 transactions'!F25 -> 525.99742
A58: ='2026 transactions'!A94 -> 46085 | B58: ='2026 transactions'!F94 -> 197.71955 | C58: ='2026 transactions'!A39 -> 46048 | D58: ='2026 transactions'!F39 -> 693.82205 | E58: ='2026 transactions'!A46 -> 46055 | F58: ='2026 transactions'!F46 -> 595.81731 | G58: ='2026 transactions'!A26 -> 46044 | H58: ='2026 transactions'!F26 -> 2710.4137
A59: ='2026 transactions'!A99 -> 46086 | B59: ='2026 transactions'!F99 -> 227.63893 | C59: ='2026 transactions'!A44 -> 46055 | D59: ='2026 transactions'!F44 -> 56.102849 | E59: ='2026 transactions'!A77 -> 46077 | F59: ='2026 transactions'!F77 -> 2147.8846 | G59: ='2026 transactions'!A28 -> 46044 | H59: ='2026 transactions'!F28 -> 188.97638
A60: ='2026 transactions'!A133 -> 46111 | B60: ='2026 transactions'!F133 -> 2974.1001 | C60: ='2026 transactions'!A51 -> 46063 | D60: ='2026 transactions'!F51 -> 93.92027 | E60: ='2026 transactions'!A79 -> 46078 | F60: ='2026 transactions'!F79 -> 294.11765 | G60: ='2026 transactions'!A40 -> 46049 | H60: ='2026 transactions'!F40 -> 262.3072
A61: ='2026 transactions'!A138 -> 46115 | B61: ='2026 transactions'!F138 -> 627.71213 | C61: ='2026 transactions'!A52 -> 46064 | D61: ='2026 transactions'!F52 -> 35.614747 | E61: ='2026 transactions'!A81 -> 46079 | F61: ='2026 transactions'!F81 -> 168.66607 | G61: ='2026 transactions'!A45 -> 46055 | H61: ='2026 transactions'!F45 -> 1316.3456
A62: ='2026 transactions'!A159 -> 46129 | B62: ='2026 transactions'!F159 -> 1469.5612 | C62: ='2026 transactions'!A58 -> 46066 | D62: ='2026 transactions'!F58 -> 371.3718 | E62: ='2026 transactions'!A88 -> 46080 | F62: ='2026 transactions'!F88 -> 1067.6425 | G62: ='2026 transactions'!A47 -> 46058 | H62: ='2026 transactions'!F47 -> 245.85998
A63: ='2026 transactions'!A174 -> 46139 | B63: ='2026 transactions'!F174 -> 811.0883 | C63: ='2026 transactions'!A61 -> 46070 | D63: ='2026 transactions'!F61 -> 89.806531 | E63: ='2026 transactions'!A98 -> 46086 | F63: ='2026 transactions'!F98 -> 513.5509 | G63: ='2026 transactions'!A48 -> 46062 | H63: ='2026 transactions'!F48 -> 418.28266
A64: ='2026 transactions'!A186 -> 46148 | B64: ='2026 transactions'!F186 -> 343.91534 | C64: ='2026 transactions'!A68 -> 46071 | D64: ='2026 transactions'!F68 -> 51.599815 | E64: ='2026 transactions'!A100 -> 46090 | F64: ='2026 transactions'!F100 -> 1354.891 | G64: ='2026 transactions'!A50 -> 46063 | H64: ='2026 transactions'!F50 -> 98.420111
A65: ='2026 transactions'!A197 -> 46157 | B65: ='2026 transactions'!F197 -> 2663.852 | C65: ='2026 transactions'!A73 -> 46073 | D65: ='2026 transactions'!F73 -> 1052.6316 | E65: ='2026 transactions'!A107 -> 46097 | F65: ='2026 transactions'!F107 -> 260.681 | G65: ='2026 transactions'!A53 -> 46064 | H65: ='2026 transactions'!F53 -> 801.66667
A66: ='2026 transactions'!A229 -> 46177 | B66: ='2026 transactions'!F229 -> 847.78291 | C66: ='2026 transactions'!A89 -> 46080 | D66: ='2026 transactions'!F89 -> 5281.3216 | E66: ='2026 transactions'!A108 -> 46098 | F66: ='2026 transactions'!F108 -> 5403.2258 | G66: ='2026 transactions'!A54 -> 46064 | H66: ='2026 transactions'!F54 -> 557.55396
A67: ='2026 transactions'!A242 -> 46183 | B67: ='2026 transactions'!F242 -> 96.682764 | C67: ='2026 transactions'!A104 -> 46092 | D67: ='2026 transactions'!F104 -> 603.23651 | E67: ='2026 transactions'!A125 -> 46107 | F67: ='2026 transactions'!F125 -> 406.34675 | G67: ='2026 transactions'!A57 -> 46065 | H67: ='2026 transactions'!F57 -> 109.34744
A68: ='2026 transactions'!A273 -> 46202 | B68: ='2026 transactions'!F273 -> 616.54393 | C68: ='2026 transactions'!A105 -> 46094 | D68: ='2026 transactions'!F105 -> 753.75978 | E68: ='2026 transactions'!A126 -> 46107 | F68: ='2026 transactions'!F126 -> 548.83333 | G68: ='2026 transactions'!A59 -> 46066 | H68: ='2026 transactions'!F59 -> 199.30806
A69: ='2026 transactions'!A289 -> 46211 | B69: ='2026 transactions'!F289 -> 170.8099 | C69: ='2026 transactions'!A109 -> 46098 | D69: ='2026 transactions'!F109 -> 58.239761 | E69: ='2026 transactions'!A127 -> 46107 | F69: ='2026 transactions'!F127 -> 419.23077 | G69: ='2026 transactions'!A60 -> 46070 | H69: ='2026 transactions'!F60 -> 998.96835
A70: ='2026 transactions'!A296 -> 46216 | B70: ='2026 transactions'!F296 -> 943.70145 | C70: ='2026 transactions'!A111 -> 46100 | D70: ='2026 transactions'!F111 -> 632.99214 | E70: ='2026 transactions'!A128 -> 46107 | F70: ='2026 transactions'!F128 -> 678.57143 | G70: ='2026 transactions'!A62 -> 46070 | H70: ='2026 transactions'!F62 -> 3629.0949
A71: ='2026 transactions'!A320 -> 46232 | B71: ='2026 transactions'!F320 -> 441.975 | C71: ='2026 transactions'!A116 -> 46104 | D71: ='2026 transactions'!F116 -> 614.22367 | E71: ='2026 transactions'!A135 -> 46112 | F71: ='2026 transactions'!F135 -> 478.14526 | G71: ='2026 transactions'!A63 -> 46070 | H71: ='2026 transactions'!F63 -> 232.08587
A72: ='2026 transactions'!A389 -> 46274 | B72: ='2026 transactions'!F389 -> 833.03299 | C72: ='2026 transactions'!A132 -> 46108 | D72: ='2026 transactions'!F132 -> 91.263823 | E72: ='2026 transactions'!A139 -> 46118 | F72: ='2026 transactions'!F139 -> 1294.6043 | G72: ='2026 transactions'!A64 -> 46070 | H72: ='2026 transactions'!F64 -> 306.66667
A73: ='2026 transactions'!A399 -> 46281 | B73: ='2026 transactions'!F399 -> 412.09022 | C73: ='2026 transactions'!A144 -> 46120 | D73: ='2026 transactions'!F144 -> 587.78036 | E73: ='2026 transactions'!A140 -> 46118 | F73: ='2026 transactions'!F140 -> 517.84173 | G73: ='2026 transactions'!A65 -> 46071 | H73: ='2026 transactions'!F65 -> 566.05161
A74: ='2026 transactions'!A415 -> 46287 | B74: ='2026 transactions'!F415 -> 67.184781 | C74: ='2026 transactions'!A146 -> 46121 | D74: ='2026 transactions'!F146 -> 508.78367 | E74: ='2026 transactions'!A154 -> 46128 | F74: ='2026 transactions'!F154 -> 117.04431 | G74: ='2026 transactions'!A66 -> 46071 | H74: ='2026 transactions'!F66 -> 387.5969
A75: ='2026 transactions'!A424 -> 46295 | B75: ='2026 transactions'!F424 -> 387.10763 | C75: ='2026 transactions'!A149 -> 46125 | D75: ='2026 transactions'!F149 -> 36.12184 | E75: ='2026 transactions'!A156 -> 46128 | F75: ='2026 transactions'!F156 -> 107.15116 | G75: ='2026 transactions'!A67 -> 46071 | H75: ='2026 transactions'!F67 -> 265.60371
C76: ='2026 transactions'!A153 -> 46127 | D76: ='2026 transactions'!F153 -> 599.0566 | E76: ='2026 transactions'!A157 -> 46128 | F76: ='2026 transactions'!F157 -> 111.9945 | G76: ='2026 transactions'!A69 -> 46071 | H76: ='2026 transactions'!F69 -> 780.89113
C77: ='2026 transactions'!A163 -> 46134 | D77: ='2026 transactions'!F163 -> 31.550911 | E77: ='2026 transactions'!A158 -> 46128 | F77: ='2026 transactions'!F158 -> 94.765682 | G77: ='2026 transactions'!A72 -> 46072 | H77: ='2026 transactions'!F72 -> 2193.7322
C78: ='2026 transactions'!A164 -> 46134 | D78: ='2026 transactions'!F164 -> 47.339571 | E78: ='2026 transactions'!A160 -> 46129 | F78: ='2026 transactions'!F160 -> 298.65605 | G78: ='2026 transactions'!A74 -> 46073 | H78: ='2026 transactions'!F74 -> 562.5
C79: ='2026 transactions'!A168 -> 46135 | D79: ='2026 transactions'!F168 -> 800.76874 | E79: ='2026 transactions'!A162 -> 46133 | F79: ='2026 transactions'!F162 -> 115.74801 | G79: ='2026 transactions'!A76 -> 46077 | H79: ='2026 transactions'!F76 -> 251.69085
C80: ='2026 transactions'!A176 -> 46140 | D80: ='2026 transactions'!F176 -> 263.7033 | E80: ='2026 transactions'!A169 -> 46135 | F80: ='2026 transactions'!F169 -> 96.591354 | G80: ='2026 transactions'!A78 -> 46078 | H80: ='2026 transactions'!F78 -> 949.26695
C81: ='2026 transactions'!A183 -> 46143 | D81: ='2026 transactions'!F183 -> 314.04714 | E81: ='2026 transactions'!A171 -> 46136 | F81: ='2026 transactions'!F171 -> 767.40007 | G81: ='2026 transactions'!A80 -> 46079 | H81: ='2026 transactions'!F80 -> 4454.5234
C82: ='2026 transactions'!A204 -> 46160 | D82: ='2026 transactions'!F204 -> 166.31642 | E82: ='2026 transactions'!A172 -> 46136 | F82: ='2026 transactions'!F172 -> 150.56584 | G82: ='2026 transactions'!A82 -> 46079 | H82: ='2026 transactions'!F82 -> 336.26103
C83: ='2026 transactions'!A205 -> 46161 | D83: ='2026 transactions'!F205 -> 1348.8872 | E83: ='2026 transactions'!A175 -> 46139 | F83: ='2026 transactions'!F175 -> 62.898121 | G83: ='2026 transactions'!A83 -> 46079 | H83: ='2026 transactions'!F83 -> 2315.1976
C84: ='2026 transactions'!A209 -> 46162 | D84: ='2026 transactions'!F209 -> 341.42516 | E84: ='2026 transactions'!A177 -> 46140 | F84: ='2026 transactions'!F177 -> 704.58806 | G84: ='2026 transactions'!A84 -> 46079 | H84: ='2026 transactions'!F84 -> 77.802317
C85: ='2026 transactions'!A211 -> 46168 | D85: ='2026 transactions'!F211 -> 1593.0039 | E85: ='2026 transactions'!A184 -> 46147 | F85: ='2026 transactions'!F184 -> 210.97046 | G85: ='2026 transactions'!A85 -> 46079 | H85: ='2026 transactions'!F85 -> 291.29347
C86: ='2026 transactions'!A217 -> 46170 | D86: ='2026 transactions'!F217 -> 268.757 | E86: ='2026 transactions'!A189 -> 46149 | F86: ='2026 transactions'!F189 -> 476.45469 | G86: ='2026 transactions'!A86 -> 46079 | H86: ='2026 transactions'!F86 -> 166.91448
C87: ='2026 transactions'!A221 -> 46171 | D87: ='2026 transactions'!F221 -> 91.453133 | E87: ='2026 transactions'!A190 -> 46154 | F87: ='2026 transactions'!F190 -> 426.33353 | G87: ='2026 transactions'!A87 -> 46079 | H87: ='2026 transactions'!F87 -> 238.71573
...
